Workbook

Sheet master
A1: Account | B1: bbgid | C1: rawTicker | D1: name | E1: lei | F1: title | G1: cusip | H1: isin | I1: ticker | J1: invCountry | K1: assetCat | L1: issuerCat | M1: derivCat | N1: counterpartyName | O1: counterpartyLei | P1: putOrCall | Q1: writtenOrPur | R1: exercisePrice | S1: exercisePriceCurCd | T1: expDt | U1: delta | V1: refInstType | W1: refIndexName | X1: refIndexIdentifier | Y1: swapFlag | Z1: terminationDt | AA1: notionalAmt | AB1: swapCurCd | AC1: unrealizedAppr | AD1: valUSD | AE1: pctVal | AF1: recFixedOrFloating | AG1: recDesc | AH1: pmntFixedOrFloating | AI1: pmntFloatingRtIndex | AJ1: pmntFloatingRtSpread | AK1: pmntPmntAmt | AL1: pmntCurCdLeg | AM1: pmntRateTenor | AN1: pmntRateUnit | AO1: refIssuerName | AP1: refIssueTitle | AQ1: refCusip | AR1: refIsin | AS1: refTicker | AT1: maturityDt | AU1: couponKind | AV1: annualizedRt | AW1: isDefault | AX1: areIntrstPmntsInArrs | AY1: isPaidKind
A2: GPTZ | C2: Cash&Other | G2: =custodian!D2
A3: ACLZ | B3: 054540208 Equity | C3: 054540208-TRS-12/01/27-L-CANT | D3: N/A | E3: N/A | F3: AXCELIS TECHNOLOGIES, INC.-SWAP-CANT-L | G3: =custodian!D3 | I3: 054540208-TRS-12/01/27-L-CANT | J3: US | K3: DE | L3: OTHER | M3: SWP | V3: otherRefInst | Y3: Y | Z3: 2027-12-01 | AA3: 485785.16 | AB3: USD | AC3: -6321.11 | AD3: -6321.11 | AE3: -2.59 | AH3: Floating | AK3: 485785.16 | AL3: USD | AO3: =BDP($B3,"ISSUER") | AP3: =BDP($B3,"NAME") | AQ3: 054540208 | AR3: =BDP($B3,"ID_ISIN") | AS3: =BDP($B3,"TICKER")
A4: ACLZ | B4: FGXXX US Equity | C4: FGXXX | D4: First American Government Obli | E4: =BDP($B4,"LEGAL_ENTITY_IDENTIFIER") | F4: First American Government Obligations Fund | G4: =custodian!D4 | H4: =BDP($B4,"ID_ISIN") | I4: FGXXX | J4: =BDP($B4,"CNTRY_OF_DOMICILE") | K4: STIV | L4: RF
A5: ACLZ | C5: Cash&Other | G5: =custodian!D5
A6: ACMM | B6: 00108J109 Equity | C6: 00108J109-TRS-07/26/27-L-MREX | D6: N/A | E6: N/A | F6: ACM RESEARCH, INC.-SWAP-MREX-L | G6: =custodian!D6 | I6: 00108J109-TRS-07/26/27-L-MREX | J6: US | K6: DE | L6: OTHER | M6: SWP | V6: otherRefInst | Y6: Y | Z6: 2027-07-26 | AA6: 519176.00 | AB6: USD | AC6: 12399.29 | AD6: 12399.29 | AE6: 4.72 | AH6: Floating | AK6: 519176.00 | AL6: USD | AO6: =BDP($B6,"ISSUER") | AP6: =BDP($B6,"NAME") | AQ6: 00108J109 | AR6: =BDP($B6,"ID_ISIN") | AS6: =BDP($B6,"TICKER")
A7: ACMM | B7: FGXXX US Equity | C7: FGXXX | D7: First American Government Obli | E7: =BDP($B7,"LEGAL_ENTITY_IDENTIFIER") | F7: First American Government Obligations Fund | G7: =custodian!D7 | H7: =BDP($B7,"ID_ISIN") | I7: FGXXX | J7: =BDP($B7,"CNTRY_OF_DOMICILE") | K7: STIV | L7: RF
A8: ACMM | C8: Cash&Other | G8: =custodian!D8
A9: AV | B9: AAL US Equity | C9: AAL | D9: American Airlines Group Inc | E9: =BDP($B9,"LEGAL_ENTITY_IDENTIFIER") | F9: American Airlines Group Inc | G9: =custodian!D9 | H9: =BDP($B9,"ID_ISIN") | I9: AAL | J9: =BDP($B9,"CNTRY_OF_DOMICILE") | K9: EC | L9: CORP
A10: AV | B10: AER US Equity | C10: AER | D10: AerCap Holdings NV | E10: =BDP($B10,"LEGAL_ENTITY_IDENTIFIER") | F10: AerCap Holdings NV | G10: =custodian!D10 | H10: =BDP($B10,"ID_ISIN") | I10: AER | J10: =BDP($B10,"CNTRY_OF_DOMICILE") | K10: EC | L10: CORP
A11: AV | B11: AIR US Equity | C11: AIR | D11: AAR Corp | E11: =BDP($B11,"LEGAL_ENTITY_IDENTIFIER") | F11: AAR Corp | G11: =custodian!D11 | H11: =BDP($B11,"ID_ISIN") | I11: AIR | J11: =BDP($B11,"CNTRY_OF_DOMICILE") | K11: EC | L11: CORP
A12: AV | B12: ALGT US Equity | C12: ALGT | D12: Allegiant Travel Co | E12: =BDP($B12,"LEGAL_ENTITY_IDENTIFIER") | F12: Allegiant Travel Co | G12: =custodian!D12 | H12: =BDP($B12,"ID_ISIN") | I12: ALGT | J12: =BDP($B12,"CNTRY_OF_DOMICILE") | K12: EC | L12: CORP
A13: AV | B13: ALK US Equity | C13: ALK | D13: Alaska Air Group Inc | E13: =BDP($B13,"LEGAL_ENTITY_IDENTIFIER") | F13: Alaska Air Group Inc | G13: =custodian!D13 | H13: =BDP($B13,"ID_ISIN") | I13: ALK | J13: =BDP($B13,"CNTRY_OF_DOMICILE") | K13: EC | L13: CORP
A14: AV | B14: ASR US Equity | C14: ASR | D14: Grupo Aeroportuario del Surest | E14: =BDP($B14,"LEGAL_ENTITY_IDENTIFIER") | F14: Grupo Aeroportuario del Sureste SAB de CV | G14: =custodian!D14 | H14: =BDP($B14,"ID_ISIN") | I14: ASR | J14: =BDP($B14,"CNTRY_OF_DOMICILE") | K14: EC | L14: CORP
A15: AV | B15: ATI US Equity | C15: ATI | D15: ATI Inc | E15: =BDP($B15,"LEGAL_ENTITY_IDENTIFIER") | F15: ATI Inc | G15: =custodian!D15 | H15: =BDP($B15,"ID_ISIN") | I15: ATI | J15: =BDP($B15,"CNTRY_OF_DOMICILE") | K15: EC | L15: CORP
A16: AV | B16: BA US Equity | C16: BA | D16: Boeing Co/The | E16: =BDP($B16,"LEGAL_ENTITY_IDENTIFIER") | F16: Boeing Co/The | G16: =custodian!D16 | H16: =BDP($B16,"ID_ISIN") | I16: BA | J16: =BDP($B16,"CNTRY_OF_DOMICILE") | K16: EC | L16: CORP
A17: AV | B17: CAE US Equity | C17: CAE | D17: CAE Inc | E17: =BDP($B17,"LEGAL_ENTITY_IDENTIFIER") | F17: CAE Inc | G17: =custodian!D17 | H17: =BDP($B17,"ID_ISIN") | I17: CAE | J17: =BDP($B17,"CNTRY_OF_DOMICILE") | K17: EC | L17: CORP
A18: AV | B18: CPA US Equity | C18: CPA | D18: Copa Holdings SA | E18: =BDP($B18,"LEGAL_ENTITY_IDENTIFIER") | F18: Copa Holdings SA | G18: =custodian!D18 | H18: =BDP($B18,"ID_ISIN") | I18: CPA | J18: =BDP($B18,"CNTRY_OF_DOMICILE") | K18: EC | L18: CORP
A19: AV | B19: CRS US Equity | C19: CRS | D19: Carpenter Technology Corp | E19: =BDP($B19,"LEGAL_ENTITY_IDENTIFIER") | F19: Carpenter Technology Corp | G19: =custodian!D19 | H19: =BDP($B19,"ID_ISIN") | I19: CRS | J19: =BDP($B19,"CNTRY_OF_DOMICILE") | K19: EC | L19: CORP
A20: AV | B20: DAL US Equity | C20: DAL | D20: Delta Air Lines Inc | E20: =BDP($B20,"LEGAL_ENTITY_IDENTIFIER") | F20: Delta Air Lines Inc | G20: =custodian!D20 | H20: =BDP($B20,"ID_ISIN") | I20: DAL | J20: =BDP($B20,"CNTRY_OF_DOMICILE") | K20: EC | L20: CORP
... A48: AV | B48: WWD US Equity | C48: WWD | D48: Woodward Inc | E48: =BDP($B48,"LEGAL_ENTITY_IDENTIFIER") | F48: Woodward Inc | G48: =custodian!D48 | H48: =BDP($B48,"ID_ISIN") | I48: WWD | J48: =BDP($B48,"CNTRY_OF_DOMICILE") | K48: EC | L48: CORP
A49: AV | C49: Cash&Other | G49: =custodian!D49
A50: BAY | B50: AAPL US Equity | C50: AAPL | D50: Apple Inc | E50: =BDP($B50,"LEGAL_ENTITY_IDENTIFIER") | F50: Apple Inc | G50: =custodian!D50 | H50: =BDP($B50,"ID_ISIN") | I50: AAPL | J50: =BDP($B50,"CNTRY_OF_DOMICILE") | K50: EC | L50: CORP
A51: BAY | B51: ABNB US Equity | C51: ABNB | D51: Airbnb Inc | E51: =BDP($B51,"LEGAL_ENTITY_IDENTIFIER") | F51: Airbnb Inc | G51: =custodian!D51 | H51: =BDP($B51,"ID_ISIN") | I51: ABNB | J51: =BDP($B51,"CNTRY_OF_DOMICILE") | K51: EC | L51: CORP
A52: BAY | B52: ADBE US Equity | C52: ADBE | D52: Adobe Inc | E52: =BDP($B52,"LEGAL_ENTITY_IDENTIFIER") | F52: Adobe Inc | G52: =custodian!D52 | H52: =BDP($B52,"ID_ISIN") | I52: ADBE | J52: =BDP($B52,"CNTRY_OF_DOMICILE") | K52: EC | L52: CORP
A53: BAY | B53: ADSK US Equity | C53: ADSK | D53: Autodesk Inc | E53: =BDP($B53,"LEGAL_ENTITY_IDENTIFIER") | F53: Autodesk Inc | G53: =custodian!D53 | H53: =BDP($B53,"ID_ISIN") | I53: ADSK | J53: =BDP($B53,"CNTRY_OF_DOMICILE") | K53: EC | L53: CORP
A54: BAY | B54: AFRM US Equity | C54: AFRM | D54: Affirm Holdings Inc | E54: =BDP($B54,"LEGAL_ENTITY_IDENTIFIER") | F54: Affirm Holdings Inc | G54: =custodian!D54 | H54: =BDP($B54,"ID_ISIN") | I54: AFRM | J54: =BDP($B54,"CNTRY_OF_DOMICILE") | K54: EC | L54: CORP
A55: BAY | B55: ALAB US Equity | C55: ALAB | D55: Astera Labs Inc | E55: =BDP($B55,"LEGAL_ENTITY_IDENTIFIER") | F55: Astera Labs Inc | G55: =custodian!D55 | H55: =BDP($B55,"ID_ISIN") | I55: ALAB | J55: =BDP($B55,"CNTRY_OF_DOMICILE") | K55: EC | L55: CORP
A56: BAY | B56: AMAT US Equity | C56: AMAT | D56: Applied Materials Inc | E56: =BDP($B56,"LEGAL_ENTITY_IDENTIFIER") | F56: Applied Materials Inc | G56: =custodian!D56 | H56: =BDP($B56,"ID_ISIN") | I56: AMAT | J56: =BDP($B56,"CNTRY_OF_DOMICILE") | K56: EC | L56: CORP
A57: BAY | B57: AMD US Equity | C57: AMD | D57: Advanced Micro Devices Inc | E57: =BDP($B57,"LEGAL_ENTITY_IDENTIFIER") | F57: Advanced Micro Devices Inc | G57: =custodian!D57 | H57: =BDP($B57,"ID_ISIN") | I57: AMD | J57: =BDP($B57,"CNTRY_OF_DOMICILE") | K57: EC | L57: CORP
A58: BAY | B58: APP US Equity | C58: APP | D58: AppLovin Corp | E58: =BDP($B58,"LEGAL_ENTITY_IDENTIFIER") | F58: AppLovin Corp | G58: =custodian!D58 | H58: =BDP($B58,"ID_ISIN") | I58: APP | J58: =BDP($B58,"CNTRY_OF_DOMICILE") | K58: EC | L58: CORP
A59: BAY | B59: AVGO US Equity | C59: AVGO | D59: Broadcom Inc | E59: =BDP($B59,"LEGAL_ENTITY_IDENTIFIER") | F59: Broadcom Inc | G59: =custodian!D59 | H59: =BDP($B59,"ID_ISIN") | I59: AVGO | J59: =BDP($B59,"CNTRY_OF_DOMICILE") | K59: EC | L59: CORP
A60: BAY | B60: BBIO US Equity | C60: BBIO | D60: Bridgebio Pharma Inc | E60: =BDP($B60,"LEGAL_ENTITY_IDENTIFIER") | F60: Bridgebio Pharma Inc | G60: =custodian!D60 | H60: =BDP($B60,"ID_ISIN") | I60: BBIO | J60: =BDP($B60,"CNTRY_OF_DOMICILE") | K60: EC | L60: CORP
A61: BAY | B61: BE US Equity | C61: BE | D61: Bloom Energy Corp | E61: =BDP($B61,"LEGAL_ENTITY_IDENTIFIER") | F61: Bloom Energy Corp | G61: =custodian!D61 | H61: =BDP($B61,"ID_ISIN") | I61: BE | J61: =BDP($B61,"CNTRY_OF_DOMICILE") | K61: EC | L61: CORP
... A109: BAY | B109: ZS US Equity | C109: ZS | D109: Zscaler Inc | E109: =BDP($B109,"LEGAL_ENTITY_IDENTIFIER") | F109: Zscaler Inc | G109: =custodian!D109 | H109: =BDP($B109,"ID_ISIN") | I109: ZS | J109: =BDP($B109,"CNTRY_OF_DOMICILE") | K109: EC | L109: CORP
A110: BAY | C110: Cash&Other | G110: =custodian!D110
A111: BLCK | B111: APLD US Equity | C111: APLD | D111: Applied Digital Corp | E111: =BDP($B111,"LEGAL_ENTITY_IDENTIFIER") | F111: Applied Digital Corp | G111: =custodian!D111 | H111: =BDP($B111,"ID_ISIN") | I111: APLD | J111: =BDP($B111,"CNTRY_OF_DOMICILE") | K111: EC | L111: CORP
A112: BLCK | B112: BKKT US Equity | C112: BKKT | D112: Bakkt Inc | E112: =BDP($B112,"LEGAL_ENTITY_IDENTIFIER") | F112: Bakkt Inc | G112: =custodian!D112 | H112: =BDP($B112,"ID_ISIN") | I112: BKKT | J112: =BDP($B112,"CNTRY_OF_DOMICILE") | K112: EC | L112: CORP
A113: BLCK | B113: BLSH US Equity | C113: BLSH | D113: Bullish | E113: =BDP($B113,"LEGAL_ENTITY_IDENTIFIER") | F113: Bullish | G113: =custodian!D113 | H113: =BDP($B113,"ID_ISIN") | I113: BLSH | J113: =BDP($B113,"CNTRY_OF_DOMICILE") | K113: EC | L113: CORP
A114: BLCK | B114: BMNR US Equity | C114: BMNR | D114: BitMine Immersion Technologies | E114: =BDP($B114,"LEGAL_ENTITY_IDENTIFIER") | F114: BitMine Immersion Technologies Inc | G114: =custodian!D114 | H114: =BDP($B114,"ID_ISIN") | I114: BMNR | J114: =BDP($B114,"CNTRY_OF_DOMICILE") | K114: EC | L114: CORP
...

Sheet custodian
A1: Date | B1: Account | C1: StockTicker | D1: CUSIP | E1: SecurityName | F1: Shares | G1: Price | H1: MarketValue | I1: Weightings | J1: NetAssets | K1: SharesOutstanding | L1: CreationUnits | M1: MoneyMarketFlag
A2: 06/25/2026 | B2: GPTZ | C2: Cash&Other | D2: Cash&Other | E2: Cash & Other | F2: 125000.00000000 | G2: 1.000000 | H2: 125000.00 | I2: 100.00% | J2: 125000.00 | K2: 5000 | L2: 1.000000000000 | M2: Y
A3: 06/25/2026 | B3: ACLZ | C3: 054540208-TRS-12/01/27-L-CANT | D3: 054540208-TRS-12/01/27-L-CANT | E3: AXCELIS TECHNOLOGIES, INC.-SWAP-CANT-L | F3: 2876.00000000 | G3: 168.910000 | H3: 485785.16 | I3: 199.21% | J3: 243854.00 | K3: 10000 | L3: 2.000000000000
A4: 06/25/2026 | B4: ACLZ | C4: FGXXX | D4: 31846V336 | E4: First American Government Obligations Fund 12/01/2031 | F4: 27380.00000000 | G4: 100.000000 | H4: 27380.00 | I4: 11.23% | J4: 243854.00 | K4: 10000 | L4: 2.000000000000 | M4: Y
A5: 06/25/2026 | B5: ACLZ | C5: Cash&Other | D5: Cash&Other | E5: Cash & Other | F5: -269435.03000000 | G5: 1.000000 | H5: -269435.03 | I5: -110.49% | J5: 243854.00 | K5: 10000 | L5: 2.000000000000 | M5: Y
A6: 06/25/2026 | B6: ACMM | C6: 00108J109-TRS-07/26/27-L-MREX | D6: 00108J109-TRS-07/26/27-L-MREX | E6: ACM RESEARCH, INC.-SWAP-MREX-L | F6: 5110.00000000 | G6: 101.600000 | H6: 519176.00 | I6: 197.73% | J6: 262568.00 | K6: 10000 | L6: 2.000000000000
A7: 06/25/2026 | B7: ACMM | C7: FGXXX | D7: 31846V336 | E7: First American Government Obligations Fund 12/01/2031 | F7: 250250.00000000 | G7: 100.000000 | H7: 250250.00 | I7: 95.31% | J7: 262568.00 | K7: 10000 | L7: 2.000000000000 | M7: Y
A8: 06/25/2026 | B8: ACMM | C8: Cash&Other | D8: Cash&Other | E8: Cash & Other | F8: -506928.75000000 | G8: 1.000000 | H8: -506928.75 | I8: -193.07% | J8: 262568.00 | K8: 10000 | L8: 2.000000000000 | M8: Y
A9: 06/25/2026 | B9: AV | C9: AAL | D9: 02376R102 | E9: American Airlines Group Inc | F9: 1230.00000000 | G9: 17.440000 | H9: 21451.20 | I9: 1.51% | J9: 1423815.00 | K9: 50000 | L9: 10.000000000000
A10: 06/25/2026 | B10: AV | C10: AER | D10: N00985106 | E10: AerCap Holdings NV | F10: 200.00000000 | G10: 147.890000 | H10: 29578.00 | I10: 2.08% | J10: 1423815.00 | K10: 50000 | L10: 10.000000000000
A11: 06/25/2026 | B11: AV | C11: AIR | D11: 000361105 | E11: AAR Corp | F11: 100.00000000 | G11: 132.940000 | H11: 13294.00 | I11: 0.93% | J11: 1423815.00 | K11: 50000 | L11: 10.000000000000
A12: 06/25/2026 | B12: AV | C12: ALGT | D12: 01748X102 | E12: Allegiant Travel Co | F12: 80.00000000 | G12: 107.320000 | H12: 8585.60 | I12: 0.60% | J12: 1423815.00 | K12: 50000 | L12: 10.000000000000
A13: 06/25/2026 | B13: AV | C13: ALK | D13: 011659109 | E13: Alaska Air Group Inc | F13: 270.00000000 | G13: 51.560000 | H13: 13921.20 | I13: 0.98% | J13: 1423815.00 | K13: 50000 | L13: 10.000000000000
A14: 06/25/2026 | B14: AV | C14: ASR | D14: 40051E202 | E14: Grupo Aeroportuario del Sureste SAB de CV | F14: 60.00000000 | G14: 302.310000 | H14: 18138.60 | I14: 1.27% | J14: 1423815.00 | K14: 50000 | L14: 10.000000000000
A15: 06/25/2026 | B15: AV | C15: ATI | D15: 01741R102 | E15: ATI Inc | F15: 170.00000000 | G15: 197.590000 | H15: 33590.30 | I15: 2.36% | J15: 1423815.00 | K15: 50000 | L15: 10.000000000000
A16: 06/25/2026 | B16: AV | C16: BA | D16: 097023105 | E16: Boeing Co/The | F16: 260.00000000 | G16: 220.250000 | H16: 57265.00 | I16: 4.02% | J16: 1423815.00 | K16: 50000 | L16: 10.000000000000
A17: 06/25/2026 | B17: AV | C17: CAE | D17: 124765108 | E17: CAE Inc | F17: 460.00000000 | G17: 24.950000 | H17: 11477.00 | I17: 0.81% | J17: 1423815.00 | K17: 50000 | L17: 10.000000000000
A18: 06/25/2026 | B18: AV | C18: CPA | D18: P31076105 | E18: Copa Holdings SA | F18: 80.00000000 | G18: 156.860000 | H18: 12548.80 | I18: 0.88% | J18: 1423815.00 | K18: 50000 | L18: 10.000000000000
A19: 06/25/2026 | B19: AV | C19: CRS | D19: 144285103 | E19: Carpenter Technology Corp | F19: 60.00000000 | G19: 580.950000 | H19: 34857.00 | I19: 2.45% | J19: 1423815.00 | K19: 50000 | L19: 10.000000000000
A20: 06/25/2026 | B20: AV | C20: DAL | D20: 247361702 | E20: Delta Air Lines Inc | F20: 600.00000000 | G20: 90.650000 | H20: 54390.00 | I20: 3.82% | J20: 1423815.00 | K20: 50000 | L20: 10.000000000000
... A24: 06/25/2026 | B24: AV | C24: FDXF | D24: 314352105 | E24: Fedex Freight Holding Co Inc | F24: 75.00000000 | G24: 160.450000 | H24: 12033.75 | I24: 0.85% | J24: 1423815.00 | K24: 50000 | L24: 10.000000000000
A25: 06/25/2026 | B25: AV | C25: FGXXX | D25: 31846V336 | E25: First American Government Obligations Fund 12/01/2031 | F25: 43839.60000000 | G25: 100.000000 | H25: 43839.60 | I25: 3.08% | J25: 1423815.00 | K25: 50000 | L25: 10.000000000000 | M25: Y
A26: 06/25/2026 | B26: AV | C26: FTAI | D26: G3730V105 | E26: FTAI Aviation Ltd | F26: 130.00000000 | G26: 272.140000 | H26: 35378.20 | I26: 2.48% | J26: 1423815.00 | K26: 50000 | L26: 10.000000000000
A27: 06/25/2026 | B27: AV | C27: GD | D27: 369550108 | E27: General Dynamics Corp | F27: 200.00000000 | G27: 344.320000 | H27: 68864.00 | I27: 4.84% | J27: 1423815.00 | K27: 50000 | L27: 10.000000000000
A28: 06/25/2026 | B28: AV | C28: GE | D28: 369604301 | E28: GE AEROSPACE | F28: 440.00000000 | G28: 365.880000 | H28: 160987.20 | I28: 11.31% | J28: 1423815.00 | K28: 50000 | L28: 10.000000000000
A29: 06/25/2026 | B29: AV | C29: HEI | D29: 422806109 | E29: HEICO Corp | F29: 70.00000000 | G29: 335.300000 | H29: 23471.00 | I29: 1.65% | J29: 1423815.00 | K29: 50000 | L29: 10.000000000000
A30: 06/25/2026 | B30: AV | C30: HWM | D30: 443201108 | E30: Howmet Aerospace Inc | F30: 260.00000000 | G30: 276.060000 | H30: 71775.60 | I30: 5.04% | J30: 1423815.00 | K30: 50000 | L30: 10.000000000000
A31: 06/25/2026 | B31: AV | C31: HXL | D31: 428291108 | E31: Hexcel Corp | F31: 160.00000000 | G31: 95.480000 | H31: 15276.80 | I31: 1.07% | J31: 1423815.00 | K31: 50000 | L31: 10.000000000000
A32: 06/25/2026 | B32: AV | C32: JBLU | D32: 477143101 | E32: JetBlue Airways Corp | F32: 1220.00000000 | G32: 5.790000 | H32: 7063.80 | I32: 0.50% | J32: 1423815.00 | K32: 50000 | L32: 10.000000000000
A33: 06/25/2026 | B33: AV | C33: JOBY | D33: G65163100 | E33: Joby Aviation Inc | F33: 1470.00000000 | G33: 9.280000 | H33: 13641.60 | I33: 0.96% | J33: 1423815.00 | K33: 50000 | L33: 10.000000000000
A34: 06/25/2026 | B34: AV | C34: LMT | D34: 539830109 | E34: Lockheed Martin Corp | F34: 120.00000000 | G34: 491.640000 | H34: 58996.80 | I34: 4.14% | J34: 1423815.00 | K34: 50000 | L34: 10.000000000000
A35: 06/25/2026 | B35: AV | C35: LOAR | D35: 53947R105 | E35: Loar Holdings Inc | F35: 160.00000000 | G35: 73.800000 | H35: 11808.00 | I35: 0.83% | J35: 1423815.00 | K35: 50000 | L35: 10.000000000000
A36: 06/25/2026 | B36: AV | C36: LUV | D36: 844741108 | E36: Southwest Airlines Co | F36: 640.00000000 | G36: 50.940000 | H36: 32601.60 | I36: 2.29% | J36: 1423815.00 | K36: 50000 | L36: 10.000000000000
A37: 06/25/2026 | B37: AV | C37: MOG/A | D37: 615394202 | E37: Moog Inc | F37: 50.00000000 | G37: 404.900000 | H37: 20245.00 | I37: 1.42% | J37: 1423815.00 | K37: 50000 | L37: 10.000000000000
... A48: 06/25/2026 | B48: AV | C48: WWD | D48: 980745103 | E48: Woodward Inc | F48: 80.00000000 | G48: 432.800000 | H48: 34624.00 | I48: 2.43% | J48: 1423815.00 | K48: 50000 | L48: 10.000000000000
A49: 06/25/2026 | B49: AV | C49: Cash&Other | D49: Cash&Other | E49: Cash & Other | F49: 493.12000000 | G49: 1.000000 | H49: 493.12 | I49: 0.03% | J49: 1423815.00 | K49: 50000 | L49: 10.000000000000 | M49: Y
A50: 06/25/2026 | B50: BAY | C50: AAPL | D50: 037833100 | E50: Apple Inc | F50: 490.00000000 | G50: 293.080000 | H50: 143609.20 | I50: 7.29% | J50: 1970766.00 | K50: 70000 | L50: 14.000000000000
A51: 06/25/2026 | B51: BAY | C51: ABNB | D51: 009066101 | E51: Airbnb Inc | F51: 140.00000000 | G51: 144.400000 | H51: 20216.00 | I51: 1.03% | J51: 1970766.00 | K51: 70000 | L51: 14.000000000000
A52: 06/25/2026 | B52: BAY | C52: ADBE | D52: 00724F101 | E52: Adobe Inc | F52: 112.00000000 | G52: 196.570000 | H52: 22015.84 | I52: 1.12% | J52: 1970766.00 | K52: 70000 | L52: 14.000000000000
A53: 06/25/2026 | B53: BAY | C53: ADSK | D53: 052769106 | E53: Autodesk Inc | F53: 84.00000000 | G53: 192.610000 | H53: 16179.24 | I53: 0.82% | J53: 1970766.00 | K53: 70000 | L53: 14.000000000000
...
